Workbook

Sheet README
A1: Liquid Alchemy Content Database v1
A2: Repo-ready workbook with normalized content sheets plus App_JSON_Export compatibility layer.
A3: Use the source tabs as canonical content. Use export/normalization sheets to generate current-app JSON.
A4: Do not treat App_JSON_Export as the source of truth; it is an app compatibility target.
A5: Images are referenced by path/status only; do not embed images.
A6: User state is excluded from canonical content.
A7: Zero-proof ABV must be calculated from ingredients[] only, never riffs/notes/lore.

Sheet Packs
A1: pack_id | B1: pack_name | C1: pack_version | D1: status | E1: recipe_count | F1: source_file | G1: created_at | H1: notes
A2: pack_000_import_20260603_2145 | B2: Imported Snapshot 2026-06-03 21:45 | C2: 1 | D2: imported_needs_review | E2: 108 | F2: 20260603_2145.json | G2: 2026-06-06 | H2: Initial import from current app JSON.
A3: pack_001_zero_proof_atk | B3: Zero-Proof ATK Spritzers & Refreshers | C3: 1 | D3: draft_needs_review | E3: 4 | F3: User-provided ATK/Claude extraction | G3: 2026-06-06 | H3: Adds four zero-proof drinks recovered from pre-Cursor/sandbox period.
A4: pack_002_attaboy_bug_family | B4: Attaboy Bug Cocktail Family | C4: 1 | D4: draft_needs_review | E4: 4 | F4: liquid_alchemy_attaboy_bug_cocktails.txt | G4: 2026-06-04 | H4: Attaboy Bug Cocktail family: Mosquito, Praying Mantis, Maverick, Lantern Fly.

Sheet Recipes
A1: recipe_id | B1: name | C1: family_id | D1: family | E1: subfamily_id | F1: subfamily | G1: base_spirit | H1: glass_id | I1: glass | J1: serve_style | K1: difficulty | L1: occasion | M1: season | N1: tags | O1: rating | P1: source_added_at | Q1: boozy | R1: sweet | S1: sour | T1: bitter | U1: fruity | V1: herbal | W1: smoky | X1: spicy | Y1: rich | Z1: pack_id | AA1: content_version | AB1: status | AC1: curiosity_hook | AD1: why_it_matters | AE1: related_recipe_ids | AF1: publish_ready | AG1: aka | AH1: obscura | AI1: craftLinks | AJ1: sourceUrl
A2: dame_blanche_au_poire | B2: Dame Blanche au Poire | C2: sour | D2: Sour | E2: daisy | F2: Daisy | G2: Gin | H2: coupe | I2: Coupe | J2: Up | K2: Easy | L2: Aperitivo | M2: Year-Round | N2: Sour/Tart, Fruity, Herbal/Botanical, Light/Refreshing, Elegant | O2: 0 | P2: 1780281499931 | Q2: 6 | R2: 4 | S2: 6 | T2: 1 | U2: 5 | V2: 0 | W2: 0 | X2: 0 | Y2: 1 | Z2: pack_000_import_20260603_2145 | AA2: 1 | AB2: imported_needs_review | AF2: FALSE | AH2: FALSE | AI2: []
A3: old_fashioned_classic | B3: Old Fashioned | C3: old_fashioned | D3: Old Fashioned | E3: core_old_fashioned | F3: Core Old Fashioned | G3: Bourbon | H3: rocks_old_fashioned | I3: Rocks/Old Fashioned | J3: On the Rocks | K3: Easy | L3: Nightcap | M3: Year-Round | N3: Boozy, Sweet, Bitter, Rich | O3: 0 | P3: 1780281499931 | Q3: 9 | R3: 4 | S3: 0 | T3: 6 | U3: 2 | V3: 0 | W3: 0 | X3: 1 | Y3: 5 | Z3: pack_000_import_20260603_2145 | AA3: 1 | AB3: imported_needs_review | AF3: FALSE | AH3: FALSE | AI3: []
A4: rosemary_fizz | B4: Rosemary Fizz | C4: sour | D4: Sour | E4: fizz | F4: Fizz | G4: Vodka | H4: coupe | I4: Coupe | J4: Up | K4: Medium | L4: Aperitivo | M4: Summer | N4: Floral, Herbal/Botanical, Fruity, Sour/Tart, Sparkling, Elegant | O4: 0 | P4: 1780270791298 | Q4: 5 | R4: 4 | S4: 4 | T4: 0 | U4: 3 | V4: 5 | W4: 0 | X4: 0 | Y4: 3 | Z4: pack_000_import_20260603_2145 | AA4: 1 | AB4: imported_needs_review | AF4: FALSE | AH4: FALSE | AI4: []
A5: first_class_pass | B5: First Class Pass | C5: highball | D5: Highball | E5: core_highball | F5: Core Highball | G5: Whiskey | H5: collins_highball | I5: Collins/Highball | J5: On the Rocks | K5: Easy | L5: Aperitivo | M5: Summer | N5: Herbal/Botanical, Floral, Light/Refreshing, Fruity, Elegant | O5: 0 | P5: 1780270198088 | Q5: 4 | R5: 3 | S5: 2 | T5: 0 | U5: 2 | V5: 5 | W5: 0 | X5: 0 | Y5: 1 | Z5: pack_000_import_20260603_2145 | AA5: 1 | AB5: imported_needs_review | AF5: FALSE | AH5: FALSE | AI5: []
A6: cold_fashioned | B6: Cold Fashioned | C6: old_fashioned | D6: Old Fashioned | E6: core_old_fashioned | F6: Core Old Fashioned | G6: Bourbon | H6: rocks_old_fashioned | I6: Rocks/Old Fashioned | J6: Frozen | K6: Medium | L6: Party | M6: Summer | N6: Boozy, Sweet, Bitter, Rich, Sour/Tart | O6: 0 | P6: 1780269740325 | Q6: 7 | R6: 4 | S6: 3 | T6: 4 | U6: 2 | V6: 0 | W6: 0 | X6: 1 | Y6: 4 | Z6: pack_000_import_20260603_2145 | AA6: 1 | AB6: imported_needs_review | AF6: FALSE | AH6: FALSE | AI6: []
A7: classic_margarita | B7: Classic Margarita | C7: sour | D7: Sour | E7: daisy | F7: Daisy | G7: Tequila | H7: other | I7: Other | J7: On the Rocks | K7: Easy | L7: Party/Batch | M7: Summer | N7: Sour/Tart, Fruity, Light/Refreshing, Sweet | O7: 0 | P7: 1780198574911 | Q7: 6 | R7: 4 | S7: 8 | T7: 1 | U7: 3 | V7: 1 | W7: 0 | X7: 0 | Y7: 1 | Z7: pack_000_import_20260603_2145 | AA7: 1 | AB7: imported_needs_review | AF7: FALSE | AH7: FALSE | AI7: []
A8: french_007 | B8: French 007 | C8: sour | D8: Sour | E8: fizz | F8: Fizz | G8: Champagne/Prosecco | H8: champagne_flute | I8: Champagne Flute | J8: Up | K8: Easy | L8: Aperitivo | M8: Year-Round | N8: Fruity, Sparkling, Sweet, Light/Refreshing, Elegant | O8: 0 | P8: 1780198575011 | Q8: 3 | R8: 5 | S8: 1 | T8: 0 | U8: 7 | V8: 0 | W8: 0 | X8: 0 | Y8: 2 | Z8: pack_000_import_20260603_2145 | AA8: 1 | AB8: imported_needs_review | AF8: FALSE | AH8: FALSE | AI8: []
A9: classic_martini | B9: Classic Martini | C9: martini_and_manhattan | D9: Martini & Manhattan | E9: martini_style | F9: Martini Style | G9: Gin | H9: martini | I9: Martini | J9: Up | K9: Medium | L9: Aperitivo | M9: Year-Round | N9: Boozy, Herbal/Botanical, Elegant, Light/Refreshing | O9: 0 | P9: 1780198574511 | Q9: 9 | R9: 1 | S9: 0 | T9: 2 | U9: 0 | V9: 7 | W9: 0 | X9: 0 | Y9: 1 | Z9: pack_000_import_20260603_2145 | AA9: 1 | AB9: imported_needs_review | AF9: FALSE | AH9: FALSE | AI9: []
A10: classic_manhattan | B10: Manhattan | C10: martini_and_manhattan | D10: Martini & Manhattan | E10: manhattan_style | F10: Manhattan Style | G10: Whiskey | H10: coupe | I10: Coupe | J10: Up | K10: Easy | L10: Nightcap | M10: Fall | N10: Boozy, Bitter, Rich, Sweet, Elegant | O10: 0 | P10: 1780198574531 | Q10: 9 | R10: 4 | S10: 0 | T10: 5 | U10: 2 | V10: 3 | W10: 0 | X10: 2 | Y10: 6 | Z10: pack_000_import_20260603_2145 | AA10: 1 | AB10: imported_needs_review | AF10: FALSE | AH10: FALSE | AI10: []
A11: classic_daiquiri | B11: Classic Daiquiri | C11: sour | D11: Sour | E11: core_sour | F11: Core Sour | G11: Rum | H11: coupe | I11: Coupe | J11: Up | K11: Easy | L11: Aperitivo | M11: Summer | N11: Sour/Tart, Light/Refreshing, Sweet, Fruity | O11: 0 | P11: 1780198574551 | Q11: 6 | R11: 4 | S11: 7 | T11: 0 | U11: 3 | V11: 0 | W11: 0 | X11: 0 | Y11: 1 | Z11: pack_000_import_20260603_2145 | AA11: 1 | AB11: imported_needs_review | AF11: FALSE | AH11: FALSE | AI11: []
A12: classic_negroni | B12: Negroni | C12: negroni | D12: Negroni | E12: unknown | G12: Gin | H12: rocks_old_fashioned | I12: Rocks/Old Fashioned | J12: On the Rocks | K12: Easy | L12: Aperitivo | M12: Year-Round | N12: Bitter, Herbal/Botanical, Boozy, Sweet, Elegant | O12: 0 | P12: 1780198574571 | Q12: 7 | R12: 4 | S12: 0 | T12: 8 | U12: 1 | V12: 6 | W12: 0 | X12: 1 | Y12: 3 | Z12: pack_000_import_20260603_2145 | AA12: 1 | AB12: imported_needs_review | AF12: FALSE | AH12: FALSE | AI12: []
A13: classic_whiskey_sour | B13: Whiskey Sour | C13: sour | D13: Sour | E13: egg_white_sour | F13: Egg White Sour | G13: Bourbon | H13: rocks_old_fashioned | I13: Rocks/Old Fashioned | J13: On the Rocks | K13: Easy | L13: Anytime | M13: Year-Round | N13: Sour/Tart, Sweet, Fruity, Creamy/Rich | O13: 0 | P13: 1780198574591 | Q13: 6 | R13: 5 | S13: 7 | T13: 1 | U13: 2 | V13: 0 | W13: 0 | X13: 1 | Y13: 4 | Z13: pack_000_import_20260603_2145 | AA13: 1 | AB13: imported_needs_review | AF13: FALSE | AH13: FALSE | AI13: []
A14: moscow_mule | B14: Moscow Mule | C14: highball | D14: Highball | E14: ginger_highball_buck | F14: Ginger Highball / Buck | G14: Vodka | H14: copper_mug | I14: Copper Mug | J14: On the Rocks | K14: Easy | L14: Party/Batch | M14: Summer | N14: Light/Refreshing, Spicy, Sparkling | O14: 0 | P14: 1780198574611 | Q14: 4 | R14: 2 | S14: 3 | T14: 0 | U14: 1 | V14: 0 | W14: 0 | X14: 5 | Y14: 0 | Z14: pack_000_import_20260603_2145 | AA14: 1 | AB14: imported_needs_review | AF14: FALSE | AH14: FALSE | AI14: []
A15: classic_cosmopolitan | B15: Cosmopolitan | C15: sour | D15: Sour | E15: daisy | F15: Daisy | G15: Vodka | H15: martini | I15: Martini | J15: Up | K15: Easy | L15: Party/Batch | M15: Year-Round | N15: Fruity, Sour/Tart, Light/Refreshing, Elegant | O15: 0 | P15: 1780198574631 | Q15: 5 | R15: 4 | S15: 6 | T15: 0 | U15: 7 | V15: 0 | W15: 0 | X15: 0 | Y15: 1 | Z15: pack_000_import_20260603_2145 | AA15: 1 | AB15: imported_needs_review | AF15: FALSE | AH15: FALSE | AI15: []
A16: aperol_spritz | B16: Aperol Spritz | C16: spritz_and_aperitivo | D16: Spritz & Aperitivo | E16: classic_spritz | F16: Classic Spritz | G16: Aperol | H16: wine_glass | I16: Wine Glass | J16: On the Rocks | K16: Easy | L16: Aperitivo | M16: Summer | N16: Light/Refreshing, Sparkling, Bitter, Fruity, Elegant | O16: 0 | P16: 1780198574651 | Q16: 2 | R16: 4 | S16: 1 | T16: 5 | U16: 4 | V16: 2 | W16: 0 | X16: 0 | Y16: 1 | Z16: pack_000_import_20260603_2145 | AA16: 1 | AB16: imported_needs_review | AF16: FALSE | AH16: FALSE | AI16: []
A17: french_75 | B17: French 75 | C17: sour | D17: Sour | E17: fizz | F17: Fizz | G17: Gin | H17: champagne_flute | I17: Champagne Flute | J17: Up | K17: Easy | L17: Aperitivo | M17: Spring | N17: Sparkling, Sour/Tart, Elegant, Light/Refreshing, Boozy | O17: 0 | P17: 1780198574671 | Q17: 6 | R17: 3 | S17: 5 | T17: 0 | U17: 1 | V17: 3 | W17: 0 | X17: 0 | Y17: 1 | Z17: pack_000_import_20260603_2145 | AA17: 1 | AB17: imported_needs_review | AF17: FALSE | AH17: FALSE | AI17: []
A18: classic_sidecar | B18: Sidecar | C18: sour | D18: Sour | E18: daisy | F18: Daisy | G18: Cognac | H18: coupe | I18: Coupe | J18: Up | K18: Easy | L18: After Dinner | M18: Fall | N18: Sour/Tart, Boozy, Sweet, Elegant | O18: 0 | P18: 1780198573511 | Q18: 7 | R18: 4 | S18: 6 | T18: 1 | U18: 2 | V18: 0 | W18: 0 | X18: 0 | Y18: 3 | Z18: pack_000_import_20260603_2145 | AA18: 1 | AB18: imported_needs_review | AF18: FALSE | AH18: FALSE | AI18: []
A19: pisco_sour | B19: Pisco Sour | C19: sour | D19: Sour | E19: egg_white_sour | F19: Egg White Sour | G19: Pisco | H19: coupe | I19: Coupe | J19: Up | K19: Medium | L19: Aperitivo | M19: Year-Round | N19: Sour/Tart, Fruity, Creamy/Rich, Light/Refreshing | O19: 0 | P19: 1780198573531 | Q19: 6 | R19: 4 | S19: 7 | T19: 2 | U19: 3 | V19: 0 | W19: 0 | X19: 0 | Y19: 4 | Z19: pack_000_import_20260603_2145 | AA19: 1 | AB19: imported_needs_review | AF19: FALSE | AH19: FALSE | AI19: []
A20: bees_knees | B20: Bee's Knees | C20: sour | D20: Sour | E20: core_sour | F20: Core Sour | G20: Gin | H20: coupe | I20: Coupe | J20: Up | K20: Easy | L20: Aperitivo | M20: Spring | N20: Sour/Tart, Herbal/Botanical, Sweet, Light/Refreshing, Elegant | O20: 0 | P20: 1780198573551 | Q20: 6 | R20: 5 | S20: 6 | T20: 1 | U20: 1 | V20: 5 | W20: 0 | X20: 0 | Y20: 2 | Z20: pack_000_import_20260603_2145 | AA20: 1 | AB20: imported_needs_review | AF20: FALSE | AH20: FALSE | AI20: []
A21: classic_gimlet | B21: Gimlet | C21: sour | D21: Sour | E21: core_sour | F21: Core Sour | G21: Gin | H21: coupe | I21: Coupe | J21: Up | K21: Easy | L21: Aperitivo | M21: Spring | N21: Sour/Tart, Herbal/Botanical, Light/Refreshing, Sweet | O21: 0 | P21: 1780198573571 | Q21: 6 | R21: 4 | S21: 7 | T21: 1 | U21: 2 | V21: 5 | W21: 0 | X21: 0 | Y21: 1 | Z21: pack_000_import_20260603_2145 | AA21: 1 | AB21: imported_needs_review | AF21: FALSE | AH21: FALSE | AI21: []
A22: southside | B22: Southside | C22: sour | D22: Sour | E22: core_sour | F22: Core Sour | G22: Gin | H22: coupe | I22: Coupe | J22: Up | K22: Easy | L22: Aperitivo | M22: Summer | N22: Sour/Tart, Herbal/Botanical, Light/Refreshing, Fruity | O22: 0 | P22: 1780198573591 | Q22: 6 | R22: 4 | S22: 6 | T22: 1 | U22: 2 | V22: 6 | W22: 0 | X22: 0 | Y22: 1 | Z22: pack_000_import_20260603_2145 | AA22: 1 | AB22: imported_needs_review | AF22: FALSE | AH22: FALSE | AI22: []
A23: clover_club | B23: Clover Club | C23: sour | D23: Sour | E23: egg_white_sour | F23: Egg White Sour | G23: Gin | H23: coupe | I23: Coupe | J23: Up | K23: Medium | L23: Aperitivo | M23: Spring | N23: Fruity, Sour/Tart, Creamy/Rich, Elegant, Floral | O23: 0 | P23: 1780198573611 | Q23: 5 | R23: 4 | S23: 5 | T23: 1 | U23: 5 | V23: 3 | W23: 0 | X23: 0 | Y23: 4 | Z23: pack_000_import_20260603_2145 | AA23: 1 | AB23: imported_needs_review | AF23: FALSE | AH23: FALSE | AI23: []
A24: rob_roy | B24: Rob Roy | C24: martini_and_manhattan | D24: Martini & Manhattan | E24: manhattan_style | F24: Manhattan Style | G24: Scotch | H24: coupe | I24: Coupe | J24: Up | K24: Easy | L24: Nightcap | M24: Winter | N24: Boozy, Bitter, Rich, Sweet, Elegant, Smoky | O24: 0 | P24: 1780198573631 | Q24: 9 | R24: 3 | S24: 0 | T24: 5 | U24: 1 | V24: 2 | W24: 4 | X24: 2 | Y24: 5 | Z24: pack_000_import_20260603_2145 | AA24: 1 | AB24: imported_needs_review | AF24: FALSE | AH24: FALSE | AI24: []
... A109: sicilian_sojourn | B109: Sicilian Sojourn | C109: highball | D109: Highball | E109: spritz | F109: Spritz | G109: Non-alcoholic | H109: collins_highball | I109: Collins/Highball | J109: On the Rocks | K109: Easy | L109: Aperitivo | M109: Winter | N109: Light/Refreshing, Sparkling, Herbal/Botanical, Fruity, Elegant | O109: 0 | P109: 1780281499905 | Q109: 0 | R109: 3 | S109: 5 | T109: 2 | U109: 7 | V109: 5 | W109: 0 | X109: 0 | Y109: 1 | Z109: pack_000_import_20260603_2145 | AA109: 1 | AB109: imported_needs_review | AF109: FALSE | AH109: FALSE | AI109: []
A110: pomegranate_spritzer | B110: Pomegranate Spritzer | C110: highball | D110: Highball | E110: spritz | F110: Spritz | G110: Non-alcoholic | H110: collins_highball | I110: Collins/Highball | J110: On the Rocks | K110: Easy | L110: Anytime | M110: Fall | N110: Light/Refreshing, Sparkling, Fruity, Bitter, Elegant | O110: 0 | P110: 1780281501000 | Q110: 0 | R110: 3 | S110: 4 | T110: 3 | U110: 7 | V110: 0 | W110: 0 | X110: 0 | Y110: 0 | Z110: pack_001_zero_proof_atk | AA110: 1 | AB110: draft_needs_review | AD110: Zero-proof base recipe. Optional alcoholic riffs must not affect ABV. | AF110: FALSE | AH110: FALSE | AI110: []
A111: hibiscus_guava_agua_fresca | B111: Hibiscus Guava Agua Fresca | C111: zero_proof | D111: Zero Proof | E111: agua_fresca | F111: Agua Fresca | G111: Non-alcoholic | H111: collins_highball | I111: Collins/Highball | J111: On the Rocks | K111: Easy | L111: Brunch | M111: Summer | N111: Light/Refreshing, Fruity, Floral, Herbal/Botanical, Sour/Tart | O111: 0 | P111: 1780281502000 | Q111: 0 | R111: 3 | S111: 5 | T111: 2 | U111: 8 | V111: 4 | W111: 0 | X111: 0 | Y111: 0 | Z111: pack_001_zero_proof_atk | AA111: 1 | AB111: draft_needs_review | AD111: Zero-proof base recipe. Optional alcoholic riffs must not affect ABV. | AF111: FALSE | AH111: FALSE | AI111: []
A112: raspberry_lime_rickey | B112: Raspberry Lime Rickey | C112: highball | D112: Highball | E112: rickey | F112: Rickey | G112: Non-alcoholic | H112: collins_highball | I112: Collins/Highball | J112: On the Rocks | K112: Medium | L112: Warm Weather | M112: Summer | N112: Light/Refreshing, Sparkling, Fruity, Sour/Tart, Elegant | O112: 0 | P112: 1780281503000 | Q112: 0 | R112: 3 | S112: 6 | T112: 0 | U112: 7 | V112: 0 | W112: 0 | X112: 0 | Y112: 0 | Z112: pack_001_zero_proof_atk | AA112: 1 | AB112: draft_needs_review | AD112: Zero-proof base recipe. Optional alcoholic riffs must not affect ABV. | AF112: FALSE | AH112: FALSE | AI112: []
A113: cantaloupe_fresno_chile_spritzer | B113: Cantaloupe and Fresno Chile Spritzer | C113: highball | D113: Highball | E113: spritz | F113: Spritz | G113: Non-alcoholic | H113: collins_highball | I113: Collins/Highball | J113: On the Rocks | K113: Easy | L113: Warm Weather | M113: Summer | N113: Light/Refreshing, Sparkling, Fruity, Spicy, Elegant | O113: 0 | P113: 1780281504000 | Q113: 0 | R113: 2 | S113: 1 | T113: 0 | U113: 8 | V113: 0 | W113: 0 | X113: 4 | Y113: 0 | Z113: pack_001_zero_proof_atk | AA113: 1 | AB113: draft_needs_review | AD113: Zero-proof base recipe. Optional alcoholic riffs must not affect ABV. | AF113: FALSE | AH113: FALSE | AI113: []
A114: mosquito | B114: Mosquito | C114: sour | D114: Sour | E114: daisy_equal_parts | F114: Daisy — Equal Parts | G114: Mezcal | H114: coupe | I114: Coupe | J114: Up | K114: Easy | L114: After Dinner | M114: Year-Round | N114: Sour/Tart, Bitter, Smoky, Spicy, Boozy | O114: 0 | P114: 1780281600000 | Q114: 6 | R114: 3 | S114: 6 | T114: 7 | U114: 2 | V114: 2 | W114: 6 | X114: 5 | Y114: 1 | Z114: pack_002_attaboy_bug_family | AA114: 1 | AB114: draft_needs_review | AC114: Sam Ross has described the equal-parts format as a balancing discipline: every component must earn its quarter of the glass. There is nowhere to hide. A weak spirit, a stale citrus, an under-sweetened ginger juice — the format exposes all of it. This is the equal-parts lesson: simplicity is the hardest standard to meet. | AD114: The Mosquito is the seed of a creative system — a template remixed from a template, now producing its own family of drinks at one of the most influential bars in contemporary craft cocktail culture. The equal-parts format, descended from the Last Word through the Paper Plane, is one of the most generative structures in modern mixology. | AE114: paper_plane,last_word | AF114: FALSE | AH114: FALSE | AI114: ["sweetened-ginger-juice"] | AJ114: https://punchdrink.com/articles/attaboy-equal-parts-cocktail-recipes/
A115: praying_mantis | B115: Praying Mantis | C115: sour | D115: Sour | E115: daisy_equal_parts | F115: Daisy — Equal Parts | G115: Scotch | H115: coupe | I115: Coupe | J115: Up | K115: Medium | L115: After Dinner | M115: Year-Round | N115: Sour/Tart, Bitter, Smoky, Boozy, Herbal/Botanical | O115: 0 | P115: 1780281600001 | Q115: 7 | R115: 2 | S115: 6 | T115: 8 | U115: 1 | V115: 5 | W115: 7 | X115: 3 | Y115: 1 | Z115: pack_002_attaboy_bug_family | AA115: 1 | AB115: draft_needs_review | AC115: Gran Classico and Campari occupy similar roles — bitter liqueur, similar color, similar ABV — but produce meaningfully different drinks. Understanding the functional differences between bitter liqueurs (sweetness level, herbal character, proof, finish) is essential to working intelligently with the Daisy template. Swapping one bitter for another is not a neutral substitution. | AD115: The most complex and demanding drink in the Bug family — a demonstration that the equal-parts template can carry serious weight when the ingredients are chosen with precision. Islay Scotch in a shaken equal-parts sour is an unusual move that works. | AE115: mosquito,paper_plane,last_word | AF115: FALSE | AH115: FALSE | AI115: ["sweetened-ginger-juice"] | AJ115: https://punchdrink.com/articles/attaboy-equal-parts-cocktail-recipes/
A116: maverick | B116: Maverick | C116: sour | D116: Sour | E116: daisy_equal_parts | F116: Daisy — Equal Parts | G116: Gin | H116: coupe | I116: Coupe | J116: Up | K116: Easy | L116: Aperitivo | M116: Year-Round | N116: Sour/Tart, Herbal/Botanical, Light/Refreshing, Fruity, Elegant | O116: 0 | P116: 1780281600002 | Q116: 5 | R116: 4 | S116: 6 | T116: 4 | U116: 2 | V116: 6 | W116: 0 | X116: 3 | Y116: 1 | Z116: pack_002_attaboy_bug_family | AA116: 1 | AB116: draft_needs_review | AC116: Shaking mint rather than muddling it is a technique choice with real consequences. Muddling ruptures the cell walls and releases chlorophyll along with the aromatics — producing a greener, more aggressive, sometimes bitter mint character. Shaking whole leaves extracts aromatics more gently. Neither is wrong; they produce different results. This drink needs the gentle version. | AD116: The Maverick closes the circle — a gin drink descended from a gin drink, routed through bourbon and mezcal along the way. The most approachable entry point into the Bug family, and a demonstration that the equal-parts template is as comfortable with lightness as with complexity. | AE116: mosquito,last_word,paper_plane | AF116: FALSE | AH116: FALSE | AI116: ["sweetened-ginger-juice"] | AJ116: https://punchdrink.com/articles/attaboy-equal-parts-cocktail-recipes/
A117: lantern_fly | B117: Lantern Fly | C117: sour | D117: Sour | E117: daisy_equal_parts | F117: Daisy — Equal Parts | G117: Rum | H117: coupe | I117: Coupe | J117: Up | K117: Medium | L117: After Dinner | M117: Year-Round | N117: Sour/Tart, Bitter, Fruity, Boozy, Spicy | O117: 0 | P117: 1780281600003 | Q117: 6 | R117: 3 | S117: 6 | T117: 7 | U117: 5 | V117: 4 | W117: 0 | X117: 4 | Y117: 2 | Z117: pack_002_attaboy_bug_family | AA117: 1 | AB117: draft_needs_review | AC117: Amargo-Vallet is a case study in how a drink's bitter component determines its character as much as the base spirit does. Swap Amargo-Vallet for Campari in this recipe and you have a different drink — same structure, same proportions, genuinely different experience. The bitter element in an equal-parts Daisy is not interchangeable. Choose it as carefully as you choose the spirit. | AD117: The most ingredient-specific drink in the Bug family, and the one most likely to reward the curious drinker who seeks it out. Amargo-Vallet is genuinely obscure outside of cocktail enthusiast circles; Jamaican pot still rum is underappreciated even among rum drinkers. The Lantern Fly puts both in a context where they cannot hide. | AE117: mosquito,paper_plane,last_word | AF117: FALSE | AH117: FALSE | AI117: ["sweetened-ginger-juice"] | AJ117: https://punchdrink.com/articles/attaboy-equal-parts-cocktail-recipes/

Sheet Ingredients
A1: ingredient_id | B1: name | C1: style | D1: flavor_notes | E1: category | F1: status
A2: absinthe | B2: Absinthe | F2: imported_needs_review
A3: agave_nectar | B3: Agave nectar | F3: imported_needs_review
A4: agave_syrup | B4: Agave syrup | F4: imported_needs_review
A5: agave_syrup_1_1 | B5: Agave syrup (1:1) | F5: imported_needs_review
A6: aged_apple_brandy_clear_creek_8_year | B6: Aged apple brandy (Clear Creek 8-year) | F6: imported_needs_review
A7: aged_rum | B7: Aged rum | F7: imported_needs_review
A8: allspice_dram | B8: Allspice dram | F8: imported_needs_review
A9: amaretto | B9: Amaretto | F9: imported_needs_review
A10: amaro | B10: Amaro | F10: imported_needs_review
A11: amaro_averna | B11: Amaro Averna | F11: imported_needs_review
A12: amaro_montenegro | B12: Amaro Montenegro | F12: imported_needs_review
A13: amaro_nonino | B13: Amaro Nonino | F13: imported_needs_review
... A224: zucca_rabarbaro | B224: Zucca Rabarbaro | F224: imported_needs_review
A225: pomegranate_juice_unsweetened | B225: Unsweetened 100% pomegranate juice | E225: juice | F225: draft_needs_review
A226: simple_syrup | B226: Simple syrup | E226: syrup | F226: draft_needs_review
A227: nonalcoholic_old_fashioned_bitters | B227: Nonalcoholic old-fashioned bitters | E227: mixer | F227: draft_needs_review
A228: seltzer_chilled | B228: Seltzer, chilled | E228: mixer | F228: draft_needs_review
A229: pomegranate_seeds | B229: Pomegranate seeds | E229: produce | F229: draft_needs_review
A230: hibiscus_tea_bags | B230: Hibiscus tea bags | E230: mixer | F230: draft_needs_review
A231: water_room_temperature | B231: Water, room temperature | E231: mixer | F231: draft_needs_review
A232: guava_nectar_chilled | B232: Guava nectar, chilled | E232: juice | F232: draft_needs_review
A233: mint_herb_syrup | B233: Mint Herb Syrup ✨ | E233: syrup | F233: draft_needs_review
A234: fresh_lemon_juice | B234: Fresh lemon juice | E234: juice | F234: draft_needs_review
A235: fresh_mint_leaves | B235: Fresh mint leaves | E235: produce | F235: draft_needs_review
A236: lemon_slices | B236: Lemon slices | E236: produce | F236: draft_needs_review
... A242: fresno_chile | B242: Fresno chile | E242: produce | F242: draft_needs_review
A243: sweetened_ginger_juice | B243: Sweetened ginger juice | D243: House Attaboy prep; see craft item sweetened-ginger-juice. | E243: juice | F243: draft_needs_review
A244: islay_scotch | B244: Islay Scotch | E244: spirit | F244: draft_needs_review
A245: gran_classico | B245: Gran Classico | E245: liqueur | F245: draft_needs_review
A246: amargo_vallet | B246: Amargo-Vallet amaro | E246: amaro | F246: draft_needs_review
A247: doctor_bird_jamaican_pot_still_rum | B247: Jamaican pot still rum (Doctor Bird recommended) | E247: spirit | F247: draft_needs_review
A248: candied_ginger | B248: Candied ginger | E248: garnish | F248: draft_needs_review

Sheet Recipe_Ingredients
A1: recipe_id | B1: sort_order | C1: ingredient_id | D1: ingredient_name_source | E1: amount | F1: unit | G1: prep | H1: note | I1: optional | J1: substitution_note
A2: dame_blanche_au_poire | B2: 1 | C2: gin_citadelle_recommended | D2: Gin (Citadelle recommended) | E2: 1.5 | F2: oz | I2: FALSE
A3: dame_blanche_au_poire | B3: 2 | C3: pear_liqueur | D3: Pear liqueur | E3: 1 | F3: oz | I3: FALSE
A4: dame_blanche_au_poire | B4: 3 | C4: fresh_lemon_juice | D4: Fresh lemon juice | E4: 0.75 | F4: oz | I4: FALSE
A5: dame_blanche_au_poire | B5: 4 | C5: citrus_peel | D5: Citrus peel | E5: 1 | F5: whole | I5: FALSE
A6: old_fashioned_classic | B6: 1 | C6: bourbon | D6: Bourbon | E6: 2 | F6: oz | I6: FALSE
A7: old_fashioned_classic | B7: 2 | C7: simple_syrup | D7: Simple syrup | E7: 0.67 | F7: oz | I7: FALSE
A8: old_fashioned_classic | B8: 3 | C8: angostura_aromatic_bitters | D8: Angostura Aromatic Bitters | E8: 5 | F8: dash | I8: FALSE
A9: old_fashioned_classic | B9: 4 | C9: angostura_orange_bitters | D9: Angostura Orange Bitters | E9: 5 | F9: dash | I9: FALSE
A10: old_fashioned_classic | B10: 5 | C10: cocktail_cherry_juice | D10: Cocktail cherry juice | E10: 1 | F10: tbsp | I10: FALSE
A11: old_fashioned_classic | B11: 6 | C11: orange_peel | D11: Orange peel | E11: 1 | F11: whole | I11: FALSE
A12: old_fashioned_classic | B12: 7 | C12: cocktail_cherry | D12: Cocktail cherry | E12: 1 | F12: whole | I12: FALSE
A13: rosemary_fizz | B13: 1 | C13: vodka_titos | D13: Vodka (Titos) | E13: 2 | F13: oz | I13: FALSE
... A522: sicilian_sojourn | B522: 6 | C522: tarragon_sprig | D522: Tarragon sprig | E522: 1 | F522: whole | I522: FALSE
A523: pomegranate_spritzer | B523: 1 | C523: pomegranate_juice_unsweetened | D523: Unsweetened 100% pomegranate juice | E523: 4 | F523: oz | I523: FALSE
A524: pomegranate_spritzer | B524: 2 | C524: simple_syrup | D524: Simple syrup | E524: 0.5 | F524: oz | I524: FALSE
A525: pomegranate_spritzer | B525: 3 | C525: nonalcoholic_old_fashioned_bitters | D525: Nonalcoholic old-fashioned bitters | E525: 0.25 | F525: tsp | H525: Traditional Angostura bitters also work but are not zero-proof. | I525: FALSE
A526: pomegranate_spritzer | B526: 4 | C526: seltzer_chilled | D526: Seltzer, chilled | E526: 4 | F526: oz | I526: FALSE
A527: pomegranate_spritzer | B527: 5 | C527: pomegranate_seeds | D527: Pomegranate seeds | E527: 1 | F527: whole | G527: garnish | I527: FALSE
A528: hibiscus_guava_agua_fresca | B528: 1 | C528: hibiscus_tea_bags | D528: Hibiscus tea bags | E528: 10 | F528: whole | G528: 100% hibiscus preferred | I528: FALSE
A529: hibiscus_guava_agua_fresca | B529: 2 | C529: water_room_temperature | D529: Water, room temperature | E529: 28 | F529: oz | I529: FALSE
A530: hibiscus_guava_agua_fresca | B530: 3 | C530: guava_nectar_chilled | D530: Guava nectar, chilled | E530: 14 | F530: oz | H530: Substitute pineapple or mango juice. | I530: FALSE
A531: hibiscus_guava_agua_fresca | B531: 4 | C531: mint_herb_syrup | D531: Mint Herb Syrup ✨ | E531: 4 | F531: oz | I531: FALSE
A532: hibiscus_guava_agua_fresca | B532: 5 | C532: fresh_lemon_juice | D532: Fresh lemon juice | E532: 2 | F532: oz | I532: FALSE
A533: hibiscus_guava_agua_fresca | B533: 6 | C533: fresh_mint_leaves | D533: Fresh mint leaves | E533: 0.25 | F533: cup | I533: FALSE
A534: hibiscus_guava_agua_fresca | B534: 7 | C534: lemon_slices | D534: Lemon slices | E534: 8 | F534: whole | G534: garnish | I534: FALSE
A535: raspberry_lime_rickey | B535: 1 | C535: sous_vide_raspberry_syrup | D535: Sous Vide Raspberry Syrup ✨ | E535: 0.75 | F535: cup | I535: FALSE
A536: raspberry_lime_rickey | B536: 2 | C536: fresh_lime_juice | D536: Fresh lime juice | E536: 0.25 | F536: cup | G536: about 2 limes | I536: FALSE
A537: raspberry_lime_rickey | B537: 3 | C537: seltzer_or_club_soda | D537: Seltzer or club soda | E537: 3 | F537: cup | I537: FALSE
A538: raspberry_lime_rickey | B538: 4 | C538: lime_slices | D538: Lime slices | E538: 4 | F538: whole | G538: garnish | I538: FALSE
A539: cantaloupe_fresno_chile_spritzer | B539: 1 | C539: cantaloupe_pieces | D539: Cantaloupe pieces | E539: 2 | F539: cup | G539: 1-inch pieces | I539: FALSE
A540: cantaloupe_fresno_chile_spritzer | B540: 2 | C540: fresno_chile | D540: Fresno chile | E540: 0.5 | F540: whole | G540: stemmed, seeded, and chopped | I540: FALSE
A541: cantaloupe_fresno_chile_spritzer | B541: 3 | C541: seltzer_chilled | D541: Seltzer, chilled | E541: 3 | F541: cup | I541: FALSE
A542: mosquito | B542: 1 | C542: mezcal | D542: Mezcal | E542: 0.75 | F542: oz | I542: FALSE
A543: mosquito | B543: 2 | C543: fresh_lemon_juice | D543: Fresh lemon juice | E543: 0.75 | F543: oz | I543: FALSE
A544: mosquito | B544: 3 | C544: sweetened_ginger_juice | D544: Sweetened ginger juice | E544: 0.75 | F544: oz | I544: FALSE
A545: mosquito | B545: 4 | C545: campari | D545: Campari | E545: 0.75 | F545: oz | I545: FALSE
A546: praying_mantis | B546: 1 | C546: islay_scotch | D546: Islay Scotch | E546: 0.75 | F546: oz | I546: FALSE
A547: praying_mantis | B547: 2 | C547: fresh_lemon_juice | D547: Fresh lemon juice | E547: 0.75 | F547: oz | I547: FALSE
A548: praying_mantis | B548: 3 | C548: sweetened_ginger_juice | D548: Sweetened ginger juice | E548: 0.75 | F548: oz | I548: FALSE
...

Sheet Steps
A1: recipe_id | B1: step_number | C1: instruction | D1: source_note
A2: dame_blanche_au_poire | B2: 1 | C2: Place the gin, pear liqueur, and lemon juice in a cocktail shaker. Cover with ice and shake vigorously until well-chilled, about 15 seconds. Strain into a chilled coupe or small tulip glass. Garnish with a citrus peel. | D2: imported_full_instruction
A3: old_fashioned_classic | B3: 1 | C3: Place a large ice cube in a rocks glass. Add the bourbon, simple syrup, both bitters, and cherry juice. Stir with a cocktail mixing spoon for a full 30 seconds until well chilled and properly diluted. Express an orange peel over the glass, run it around the rim, and drop it in. Garnish with a cocktail cherry. | D3: imported_full_instruction
A4: rosemary_fizz | B4: 1 | C4: Add strawberries and one and a half rosemary sprigs to a shaker with simple syrup and muddle. Add egg white, vodka, and lemon juice. Dry shake without ice for at least 15 seconds to build the foam. Add ice and St-Germain and shake again for 15 more seconds. Double strain into a coupe or rocks glass over fresh ice. Top with Prosecco. Garnish with a rosemary sprig. | D4: imported_full_instruction
A5: first_class_pass | B5: 1 | C5: Add cucumber slices and mint leaves to a shaker and muddle gently — bruise the cucumber and press the mint just enough to release the oils without shredding. Add Irish whiskey, elderflower liqueur, vodka, honey syrup, and lime juice. Add ice and shake well. Double strain through a fine strainer into an ice-filled highball glass. Top with chilled yuzu soda. Garnish with a lime wheel and mint sprig. | D5: imported_full_instruction
A6: cold_fashioned | B6: 1 | C6: Add all ingredients to a blender and blend until smooth. Serve in a rocks glass. Garnish with a brulee sugar crisp. For the Old Fashioned mix: combine 150ml black tea, 150g sugar, and 14 dashes aromatic bitters. Stir until sugar dissolves. For the citrus blend: combine 2 parts fresh lemon juice, 1 part fresh orange juice, 1 part fresh grapefruit juice. For the brulee sugar crisp: cut the end off an orange and place it upside down on a jigger. Spread 1 barspoon sugar over the center, add 8-10 drops aromatic bitters, then caramelize with a kitchen torch until fully browned and bubbling. Add a pinch of flaky sea salt as it cools. | D6: imported_full_instruction
A7: classic_margarita | B7: 1 | C7: Prepare a margarita glass with a salted rim. Add tequila, Cointreau, lime juice, and agave syrup to a shaker tin. Add ice and shake hard for 15 seconds. Strain over fresh ice into the prepared glass. Garnish with a lime wheel. | D7: imported_full_instruction
A8: french_007 | B8: 1 | C8: Add the pear and pomegranate liqueurs to a chilled champagne flute. Top with dry champagne or sparkling wine. No stirring needed — the bubbles will do the work. | D8: imported_full_instruction
A9: classic_martini | B9: 1 | C9: Stir gin, vermouth, and bitters with ice for 30-40 seconds until well chilled and properly diluted. Strain into a chilled martini or coupe glass. Express a lemon peel over the surface and either drop it in or perch it on the rim. | D9: imported_full_instruction
A10: classic_manhattan | B10: 1 | C10: Combine whiskey, vermouth, and bitters in a mixing glass with ice. Stir for 30 seconds until well chilled. Strain into a chilled coupe or Nick & Nora glass. Garnish with a cocktail cherry. | D10: imported_full_instruction
A11: classic_daiquiri | B11: 1 | C11: Combine all ingredients in a shaker with ice. Shake hard for 15 seconds. Double strain into a chilled coupe. | D11: imported_full_instruction
A12: classic_negroni | B12: 1 | C12: Combine gin, Campari, and sweet vermouth in a mixing glass with ice. Stir for 30 seconds. Strain over a large ice cube in a rocks glass. Express an orange peel over the surface and drop it in. | D12: imported_full_instruction
A13: classic_whiskey_sour | B13: 1 | C13: Dry shake all ingredients without ice for 15 seconds to emulsify the egg white. Add ice and shake hard for another 15 seconds. Strain into a rocks glass over ice. Dash bitters on the foam and drag a toothpick through for a decorative pattern. | D13: imported_full_instruction
... A106: lantern_fly | B106: 1 | C106: Combine all ingredients in a cocktail shaker with ice. Shake until well chilled. Strain into a chilled coupe. Garnish with candied ginger. | D106: attaboy_bug_family_import

Sheet Garnishes
A1: recipe_id | B1: sort_order | C1: garnish | D1: prep | E1: placement | F1: source_note
A2: dame_blanche_au_poire | B2: 1 | C2: Citrus peel | F2: imported_from_ingredients
A3: old_fashioned_classic | B3: 1 | C3: Cocktail cherry juice | F3: imported_from_ingredients
A4: old_fashioned_classic | B4: 2 | C4: Orange peel | F4: imported_from_ingredients
A5: old_fashioned_classic | B5: 3 | C5: Cocktail cherry | F5: imported_from_ingredients
A6: rosemary_fizz | B6: 1 | C6: Fresh rosemary sprigs | F6: imported_from_ingredients
A7: first_class_pass | B7: 1 | C7: Fresh cucumber slices | F7: imported_from_ingredients
A8: first_class_pass | B8: 2 | C8: Fresh mint leaves | F8: imported_from_ingredients
A9: classic_margarita | B9: 1 | C9: Lime wheel | F9: imported_from_ingredients
A10: classic_martini | B10: 1 | C10: Lemon peel | F10: imported_from_ingredients
A11: classic_manhattan | B11: 1 | C11: Cocktail cherry | F11: imported_from_ingredients
A12: classic_negroni | B12: 1 | C12: Orange peel | F12: imported_from_ingredients
A13: moscow_mule | B13: 1 | C13: Lime wheel | F13: imported_from_ingredients
... A50: sicilian_sojourn | B50: 1 | C50: Tarragon sprig | F50: imported_from_ingredients
A51: mosquito | B51: 1 | C51: Candied ginger | E51: coupe rim or pick | F51: attaboy_bug_family_import
A52: praying_mantis | B52: 1 | C52: Candied ginger | E52: coupe rim or pick | F52: attaboy_bug_family_import
A53: maverick | B53: 1 | C53: Candied ginger | E53: coupe rim or pick | F53: attaboy_bug_family_import
A54: lantern_fly | B54: 1 | C54: Candied ginger | E54: coupe rim or pick | F54: attaboy_bug_family_import

Sheet Lore
A1: recipe_id | B1: story | C1: origin | D1: why_it_works | E1: curiosity_hook | F1: notes | G1: riffs | H1: tasting_notes | I1: creator_id | J1: source_urls | K1: source_notes | L1: review_status
A2: dame_blanche_au_poire | B2: The Dame Blanche is a classic gin sour from the golden age of cocktails, named after the Belgian legend of a white-robed spirit said to haunt mountain passes. Structurally it belongs to the Sour family — spirit, citrus, sweetener — here elevated with pear liqueur for a delicate floral character. | F2: Recipe by @bridget7487049 via ReciMe. Citadelle gin is recommended but any quality London Dry works well. | I2: bridget7487049_via_recime | L2: needs_review
A3: old_fashioned_classic | B3: The Old Fashioned is the oldest known cocktail, dating to the early 1800s — originally called simply a 'cocktail': a spirit, sugar, water, and bitters. The name came later when drinkers began requesting it 'the old-fashioned way' as bartenders started adding juices and liqueurs. It is the template from which nearly all stirred, spirit-forward cocktails descend. | F3: The 30-second stir is non-negotiable — it's what makes the texture silky. Use a good bourbon with some proof (100+) since the dilution will soften it. | L3: needs_review
A4: rosemary_fizz | B4: Created by Damon Williams at Baytowne Provisions in South Walton, Florida — a beachside bar on the Gulf Coast that is not famous and does not need to be. The lineage is what matters here: an egg white sour with elderflower and a sparkling wine top, muddled rosemary and strawberry as the aromatic foundation. The thread runs from the classic Fizz template through the St-Germain era of modern American craft bartending all the way to a bar on the Emerald Coast. Every cocktail has a lineage. This one traces from Paris to New York to the Florida Panhandle, and it is a very good drink. | F4: The St-Germain is added with the ice in the second shake rather than the first — a deliberate choice to protect its delicate floral aromatics from the aggressive friction of the dry shake. It is a small detail that makes a difference. Dry shake for the full 15 seconds; the foam needs the time. Two small strawberries rather than one large one gives better muddling coverage. | G4: Substitute gin for vodka for a more botanical result that leans into the rosemary and elderflower. Omit the Prosecco and serve straight up as a Royale variation. Blackberries in place of strawberries for an autumn version. | L4: needs_review
A5: first_class_pass | B5: An evolution of an original recipe by Jack McGarry, managing partner of The Irish Exit in New York City — the sister bar to The Dead Rabbit, one of the most celebrated cocktail bars in the world. The drink matches cucumber and mint against the floral, herbal character of Irish whiskey, a pairing so natural it is surprising it is not more common. The elderflower liqueur ties both together. The yuzu soda adds a citrus brightness that keeps the whole thing from becoming heavy despite the multiple flavor elements at play. | F5: Fever-Tree Lime and Yuzu is the house soda at The Irish Exit — it is worth tracking down. In a pinch, any yuzu-forward soda or a combination of yuzu juice and plain soda water will work. Double strain to remove mint fragments and cucumber seeds. The small amounts of vodka and lime are balancers rather than primary flavors — do not skip them. Honey syrup is 1:1 honey to warm water, stirred until dissolved. | G5: Substitute gin for Irish whiskey for a more botanical result. Add a barspoon of St-Germain in place of the elderflower liqueur for a slightly richer floral note. | L5: needs_review
A6: cold_fashioned | B6: A house cocktail from Still Austin Whiskey Co., the first whiskey distillery in Austin city limits since Prohibition. Still Austin is a grain-to-glass operation — milling, mashing, fermenting, distilling, barreling, and bottling entirely in-house — and The Musician bourbon, their flagship, is what the drink is built around. The Cold Fashioned is served at their distillery bar on the east side of Austin, alongside tours, live music, and a seafood food truck on the patio. The recipe was popularized online by Austin-based mixologist Reid Nelson (@reidbetweenthelimes), who recreated the Still Austin version at home with characteristic attention to technique and garnish detail. The brulee sugar crisp is the signature detail: sugar, aromatic bitters, and flaky sea salt caramelized on an orange slice with a kitchen torch. The xanthan gum note is worth heeding — a quarter teaspoon is the difference between a smooth frozen cocktail and a separated one. | F6: Xanthan gum is optional but recommended for texture — it prevents the blend from separating and gives the drink a smoother, more uniform consistency. A small amount goes a long way. Pre-made old fashioned mix and sour mix can substitute for the house-made versions but the scratch version is dramatically better. The brulee sugar crisp can be made ahead and stored briefly. | G6: Scale down to a single serving: 1.5oz bourbon, 0.75oz old fashioned mix, 2oz citrus blend, small pinch of xanthan gum, 4oz pebble ice. Substitute rye for a spicier result. | L6: needs_review
A7: classic_margarita | B7: The Margarita is technically a Daisy — a sour cocktail made with a base spirit, citrus, and an orange liqueur, served in a salt-rimmed glass. In fact, margarita is Spanish for daisy. It belongs to the same family as the Sidecar and Cosmopolitan, and is one of the most ordered cocktails in the world. Its precise origin is disputed, with several bartenders and socialites from the 1930s-50s claiming credit. | F7: Use the best blanco tequila you can — it makes an enormous difference. Agave syrup at 1:1 (agave:water) keeps the sweetness clean and true to the spirit. | G7: Tommy Margarita: agave nectar instead of triple sec, on the rocks. Mezcal Margarita: substitute mezcal for tequila for a smoky version. Spicy Margarita: add jalapeno-infused tequila or muddle fresh chile. | L7: needs_review
A8: french_007 | B8: The French 007 is a champagne cocktail in the Kir Royale tradition — a style dating to post-war Burgundy, where Canon Félix Kir popularized the combination of crème de cassis and white wine. By substituting fruit liqueurs for cassis and using champagne, the format becomes endlessly riffable. The name nods to its Franco-elegant character — shaken, not stirred optional. | F8: The Mathilde Poire and Pama create a beautiful rose-gold color in the glass. Use a genuinely dry champagne or crémant to keep it from tipping too sweet. | G8: Substitute rye for bourbon for a spicier, drier result. Add a barspoon of honey syrup for a Gold Rush variation. | L8: needs_review
A9: classic_martini | B9: The Martini is arguably the most iconic cocktail in existence, its origins disputed between New York and San Francisco in the 1880s. It belongs to no family — it IS a family, the template from which the Manhattan, the Negroni, and countless others descend. Churchill famously chilled his gin by glancing at the vermouth bottle. James Bond's insistence on shaking it is, to purists, a cardinal sin. | F9: The ratio is everything — 5:1 is bone dry, 3:1 is classic, 2:1 is a wet martini. Chill your glass in the freezer. Never shake unless specifically asked — it bruises the gin and clouds the drink. | G9: Gibson: substitute a cocktail onion garnish for the olive. Dirty Martini: add a barspoon of olive brine. Vesper: add 0.5 oz Lillet Blanc and substitute vodka for half the gin. | L9: needs_review
A10: classic_manhattan | B10: The Manhattan was born in New York City in the 1870s, with the Manhattan Club claiming credit. It is the oldest known stirred whiskey cocktail and the direct ancestor of the Rob Roy (Scotch), the Black Manhattan (Averna), and the Toronto (Fernet). Along with the Old Fashioned and Martini it forms the holy trinity of classic American cocktails. | F10: Rye gives a spicier, drier result; bourbon gives a softer, sweeter one. Use a quality sweet vermouth — Carpano Antica is the gold standard. The cherry matters — use a Luxardo, not a maraschino. | G10: Rob Roy: substitute Scotch for rye. Black Manhattan: substitute Averna amaro for sweet vermouth. Perfect Manhattan: split sweet and dry vermouth equally. | L10: needs_review
A11: classic_daiquiri | B11: The Daiquiri was born in the mining town of Daiquirí, Cuba around 1900, popularized by American engineer Jennings Cox. It belongs to the Sour family — spirit, citrus, sweetener — and is considered the purist's test of a bartender's skill. Hemingway famously drank them by the pitcher at El Floridita in Havana, though he requested his without sugar — the Papa Doble. | F11: The Daiquiri is a bartender's benchmark — deceptively simple, ruthlessly revealing of technique and ingredient quality. Use fresh lime juice only. The ratio of sweet to sour is the whole game — taste and adjust before shaking. | G11: Hemingway Daiquiri: add grapefruit juice and maraschino, no sugar. Banana Daiquiri: add banana liqueur. Strawberry Daiquiri: blend with fresh strawberries. | L11: needs_review
A12: classic_negroni | B12: The Negroni was born in Florence in 1919 when Count Camillo Negroni asked bartender Fosco Scarselli to strengthen his Americano by replacing the soda water with gin. It belongs to the equal-parts family and is the gateway drug to the world of bitter, amaro-driven cocktails. The Sbagliato (with prosecco), Boulevardier (with bourbon), and Mezcal Negroni are its most celebrated variations. | F12: Equal parts is the rule — resist the urge to increase the gin. The Negroni rewards patience; stir it longer than you think necessary. Substituting bourbon for gin gives you a Boulevardier. | G12: Boulevardier: substitute bourbon for gin. Mezcal Negroni: substitute mezcal for gin. Sbagliato: substitute Prosecco for gin. White Negroni: substitute Suze and Lillet Blanc. | L12: needs_review
A13: classic_whiskey_sour | B13: The Whiskey Sour dates to at least 1862, appearing in Jerry Thomas's seminal bartending guide. It represents the entire Sour family — spirit, citrus, sweetener — which is the most important template in cocktail making. The addition of egg white elevates it to a Fizz or Boston Sour. Nearly every fruit-forward modern cocktail traces its lineage to this template. | F13: The egg white is optional but transforms the texture — silky and luxurious. The dry shake first is essential to build the foam. For a Boston Sour, serve up in a coupe. | G13: New York Sour: float red wine on top. Boston Sour: add egg white. Add a dash of Angostura bitters for more structure. | L13: needs_review
A14: moscow_mule | B14: The Moscow Mule was invented in 1941 at the Cock 'n' Bull pub in Los Angeles as a marketing collaboration between Smirnoff vodka and a ginger beer company. Its signature copper mug was a stroke of branding genius. It represents the Highball family — spirit, mixer, ice — the simplest and most refreshing cocktail template, and the one responsible for popularizing vodka in America. | F14: The copper mug is traditional and does keep the drink colder longer. Use a spicy, full-flavored ginger beer — Fever-Tree or Bundaberg work well. Substituting dark rum gives you a Dark & Stormy. | G14: Dark and Stormy: substitute dark rum for vodka. Kentucky Mule: substitute bourbon. Mexican Mule: substitute tequila. | L14: needs_review
A15: classic_cosmopolitan | B15: The Cosmopolitan was popularized by bartender Toby Cecchini at The Odeon in New York in 1988, though earlier versions existed in Florida and Provincetown. It became a cultural phenomenon through Sex and the City in the late 1990s, making it one of the most recognizable cocktails in the world. Technically a Daisy — spirit, citrus, orange liqueur — it shares its DNA with the Margarita and Sidecar. | F15: Use just enough cranberry juice to give the drink its signature blush — more than half an ounce and it tips too sweet. Citrus vodka is traditional but a clean neutral vodka works equally well. | G15: Add a float of Cointreau for extra orange richness. Substitute blood orange juice for regular cranberry for a seasonal variation. | L15: needs_review
... A43: dangerous_passion | B43: Created at a beachside bar in Aruba, the Dangerous Passion — El Azarosa Passionato in its original Spanish-Italian — is a masterclass in the seductive tension between tropical sweetness and slow-building heat. The passion fruit opens bright and floral, the ginger adds warmth, and the Ancho Reyes delivers a long, smoky chile finish. The flamed garnish is theatre as much as technique — the scorched habanero releases capsaicin aromatics that prime the palate before the first sip. A cocktail that lives up to its name. | F43: The flamed garnish is essential to the experience — the scorched habanero and toasted cardamom transform the aromatic profile entirely. Fresh passion fruit juice is strongly preferred; bottled works but loses the floral brightness. Teremana Reposado brings a gentle oak and vanilla quality that bridges the fruit and heat beautifully. | G43: Substitute gin for vodka for a more botanical version. Add a barspoon of grenadine for a deeper, richer color. | L43: needs_review
A44: monte_cassino | F44: From Steve the Bartender's Top 10 list. | G44: Substitute Yellow Chartreuse for Green for a softer, less assertive variation. | L44: needs_review
A45: flor_de_jerez | F45: From Steve the Bartender's Top 10 list. | G45: Substitute fino sherry for manzanilla for a nuttier, more oxidized character. | L45: needs_review
A46: bicycle_thief | F46: From Steve the Bartender's Top 10 list. | G46: Add a barspoon of grenadine for a fruitier, deeper result. | L46: needs_review
A47: kentucky_buck | F47: By @BartenderAtLarge. From Steve the Bartender's Top 10 list. | G47: Moscow Mule: substitute vodka for bourbon. Mexican Mule: substitute tequila. | L47: needs_review
A48: bitter_giuseppe | F48: Original specs from Steve the Bartender's Top 10 list. | G48: Add a barspoon of Fernet-Branca for an intensely bitter, digestif-style variation. | L48: needs_review
A49: siesta | F49: From Steve the Bartender's Top 10 list. | G49: Substitute Aperol for Campari for a softer, less bitter result. | L49: needs_review
A50: monella_sour | F50: From Steve the Bartender's Top 10 list. | G50: Substitute mezcal for the base spirit for a smoky variation. | L50: needs_review
A51: shakedown_street | F51: From Steve the Bartender's Top 10 list. | G51: Substitute bourbon for rye for a sweeter, rounder result. | L51: needs_review
A52: black_prince | F52: From Steve the Bartender's Top 10 list. | G52: Add a barspoon of blackberry liqueur for a fruitier, deeper result. | L52: needs_review
A53: muddled_mission | F53: From Steve the Bartender's Top 10 list. | G53: Substitute gin for vodka for a more botanical variation. | L53: needs_review
A54: bad_birdy_sangria | B54: Created by mixologist Bad Birdy, this elevated Sangria riff layers citrus, warm spice, and tropical fruit over a medium-bodied red wine base, with brandy adding depth and a splash of Coke lifting the whole thing with a whisper of sweetness and fizz. It drinks like a party in a glass. | F54: Created by mixologist Bad Birdy. Garnish with a mint sprig and lime wheel. | G54: Adjust the fruit selection seasonally — stone fruit in summer, citrus in winter. | L54: needs_review
A55: rattlesnake | B55: Created by Natasha David in New York City. David herself admits she is not a huge fan of egg whites or absinthe — yet finds the Rattlesnake unexpectedly balanced. As she puts it: ingredients in the right proportions create harmony, even if they are not always up your alley. A frothy, absinthe-spiked Whiskey Sour that earns its name. | F55: Garnish: Angostura bitters swirl. | G55: Omit the absinthe rinse for a more straightforward whiskey sour. The Corpse Reviver No. 2 shares the absinthe rinse technique. | L55: needs_review
A56: fresh_fruit_citronade | B56: Started life as an Applebee's menu item — proof that chain restaurants occasionally stumble onto something worth stealing. Re-specced for Alchemy with fresh lemon, Solerno, and an extra crack of pepper. A dirty pour keeps the muddled fruit and broken ice in the glass, layering the flavor from first sip to last. Sorry, Applebee's. | F56: The dirty pour keeps the muddled fruit in the glass, creating layered flavor as you drink. The black pepper is the secret — do not skip it. Solerno bridges the citrus and strawberry beautifully; Cointreau works as a substitute. | G56: The original Applebee's spec that started this: 1.5 oz citron vodka, 2 fresh strawberries, 3 basil leaves, pinch of black pepper, good quality lemonade, seltzer. Build in glass — muddle strawberries, pepper, and basil gently, add vodka and ice and stir, top with lemonade and seltzer, then gently lift and stir to combine. The current Alchemy spec is a proper cocktail rebuild of that same spirit. | L56: needs_review
A57: berry_gin_fizz | B57: Discovered on a German cocktail website, this is a modern riff on the classic Gin Fizz — one of the most enduring cocktail families of the 1920s. The addition of fresh berries gives it a playful, summery character that feels entirely contemporary. The Fizz family template — spirit, citrus, sweetener, soda — is one of the most riff-able in the cocktail canon. | F57: The recipe calls for The Great Eight Gin, an Austrian craft dry gin from the Peter Affenzeller distillery in Upper Austria, named for its eight botanicals. Any quality dry gin works beautifully. Use raspberries for tartness, blueberries for a deeper, earthier note, or a mix of both. | L57: needs_review
A58: rosemary_gin_smash | B58: The Smash is one of cocktailing oldest templates — spirit, herb, sugar, and seasonal fruit, dating to at least 1862. The modern gin-and-herb interpretation was pioneered by German bartender Jorg Meyer, whose Gin Basil Smash (created in 2008 at Le Lion in Hamburg) inspired a generation of herb-forward riffs. This rosemary version follows that lineage: clean, aromatic, and deeply refreshing. Found on a German cocktail website featuring The Great Eight Gin, an Austrian craft dry gin from the Peter Affenzeller distillery. | F58: Built in the glass with no shaking — try it as written first for comparison, then try shaking for more dilution and a colder result. The Great Eight Gin is an Austrian craft dry gin from the Peter Affenzeller distillery in Upper Austria. Any quality dry gin with botanical character works well here. | G58: The direct ancestor of this drink is the Gin Basil Smash, created by German bartender Jorg Meyer at Le Lion in Hamburg in 2008 — same template, basil instead of rosemary. Worth making both back to back. | L58: needs_review
A59: morgenthaler_amaretto_sour | B59: In 2012, Jeffrey Morgenthaler published a post titled I Make the Best Amaretto Sour in the World. The craft cocktail world had spent a decade treating the Amaretto Sour as a punchline. Morgenthaler disagreed. His revamped version adds overproof bourbon for backbone and egg white for texture, transforming a drink everyone had written off into something genuinely elegant. It is now considered a modern classic and a defining moment of the cocktail revival — proof that rehabilitation is possible. Search Morgenthaler to find all three of his recipes in the collection. | F59: The overproof bourbon is non-negotiable — it provides the backbone that makes this drink work. Without it, the amaretto overwhelms. Overproof means 100 proof (50% ABV) or higher; the higher the better. Morgenthaler recommends Bookers (typically 120-130 proof, uncut and unfiltered straight from the barrel), and he also recommends Old Grand-Dad 114 as an excellent, more accessible option. Any cask-strength bourbon in the 110-130 proof range will work beautifully. Dry shake first to build the foam, then shake with ice. Fine strain to keep it clean. Luxardo amaretto is also recommended. | L59: needs_review
A60: tia_mia | B60: In the mid-2000s, Ivy Mix had a habit of floating a splash of mezcal on cocktails she liked — including the Mai Tai. Around 2010, working at Lani Kai in New York, she committed to a full ounce and the Tia Mia was born. A mezcal-and-Jamaican-rum riff on Trader Vic 1944 original, it quickly earned a following among New York bartenders and drinkers and is now considered a modern tropical classic. Mix went on to co-found Leyenda in Brooklyn, a pan-Latin cocktail bar ranked among the world best, and to write Spirits of Latin America — a book that treats Latin spirits as cultural history, travel, and place, not just bottles on a backbar. | Search Ivy Mix to find more of her recipes. | F60: The name is a play on Mai Tai — swap the letters. Tia Mia is also Spanish for my aunt, the name Mix gave to a regular she knew in Guatemala. Use a smoky, expressive mezcal — Del Maguey Vida is the classic choice. Jamaican rum brings funk and depth; any full-bodied aged Jamaican rum works. Crushed ice is part of the identity. | G60: The Mai Tai is the direct ancestor — substitute curacao for orgeat and lime for the base. | L60: needs_review
A61: negroni_sbagliato | B61: Sbagliato means mistaken in Italian. At Bar Basso in Milan sometime in the 1970s, bartender Mirko Stocchetto was making a Negroni during a busy service and accidentally reached for a bottle of Prosecco instead of gin. Rather than discard it, he served it. The guest loved it. It became a house specialty and eventually a global classic. In 2022 a viral TikTok interview with House of the Dragon actress Olivia Cooke — in which she ordered a Negroni Sbagliato with Prosecco in a particular tone of voice — made it briefly the most Googled cocktail in the world. The happy accident has never looked back. | F61: Do not shake. Do not over-stir. The Prosecco is delicate and the bubbles are part of the drink. Use a good Prosecco — it is a third of the cocktail. Cava works beautifully as a slightly drier alternative. | G61: The classic Negroni: substitute gin for Prosecco. Large-Batch version: equal bottles of each ingredient in a punch bowl. | L61: needs_review
A62: americano_cocktail | B62: The Americano traces directly to the Milano Torino — equal parts Campari and sweet vermouth — which had been popular in Italy since the 1860s. When American soldiers arrived in Italy during World War I, many found the Mi-To too bitter and too strong. Italian bartenders began adding soda water to lengthen and lighten it for their American guests. The name stuck. It is one of the oldest drinks in the Campari lineage and the direct precursor to the Negroni — Count Camillo Negroni simply asked his bartender to replace the soda with gin. | F62: The Americano is the ancestor of the Negroni — substitute gin for the soda water and you have one. Lower-ABV, endlessly refreshing, and the perfect introduction to the bitter aperitivo style. James Bond orders one in the first chapter of Casino Royale — his very first drink in the entire canon. | G62: Negroni: add gin. Sbagliato: substitute Prosecco for soda. | L62: needs_review
A63: french_blonde | B63: The French Blonde is gin, Lillet Blanc, fresh grapefruit, and St-Germain elderflower — a drink that sits somewhere between a Greyhound and a White Negroni, floral and citrus-bright and unmistakably French in character. It came to widespread attention when US Weekly reported it as Taylor Swift favorite cocktail during the Eras Tour era — and if the Eras Tour can boost the global economy, a Swift endorsement was always going to move bottles of Lillet. Bartenders everywhere had better know how to make it. The good news: it deserves the attention entirely on its own merits. | F63: Use fresh grapefruit juice — not bottled. Oro Blanco (white grapefruit) gives the palest, most elegant color. Pink grapefruit works just as well and adds a peachy hue. A London dry gin is traditional but a citrus-forward gin elevates the floral notes beautifully. | L63: needs_review
